<?xml version="1.0" encoding="utf-8"?>
<!-- =================================================================================== -->
<!-- |    This document was autogenerated by xacro from finger.urdf.xacro              | -->
<!-- |    EDITING THIS FILE BY HAND IS NOT RECOMMENDED                                 | -->
<!-- =================================================================================== -->
<robot>
  <link name="dummy">
    <inertial>
      <mass value="0"/>
      <inertia ixx="0.0" ixy="0.0" ixz="0.0" iyy="0.0" iyz="0.0" izz="0.0"/>
    </inertial>
  </link>
  <link name="0-xm430_0">
    <inertial>
      <origin rpy="0 0 0" xyz="-4.0773796e-3 -1.5304911e-2 -1.6871895e-2"/>
      <mass value="0.082"/>
      <inertia ixx="2.3729564e-5" ixy="-1.3079758e-7" ixz="-8.1403365e-8" iyy="1.3112295e-5" iyz="-1.9659314e-6" izz="2.0942871e-5"/>
    </inertial>
    <visual>
      <origin rpy="0.0 0.0 0.0" xyz="0.0 0.0 0.0"/>
      <geometry>
        <mesh filename="./mesh/xm430.obj" scale="0.001 0.001 0.001"/>
      </geometry>
    </visual>
    <collision>
      <origin rpy="0.0 0.0 0.0" xyz="0.0 0.0 0.0"/>
      <geometry>
        <mesh filename="./mesh/xm430.obj" scale="0.001 0.001 0.001"/>
      </geometry>
    </collision>
  </link>
  <link name="0-xm430_1">
    <inertial>
      <origin rpy="0 0 0" xyz="-4.0773796e-3 -1.5304911e-2 -1.6871895e-2"/>
      <mass value="0.082"/>
      <inertia ixx="2.3729564e-5" ixy="-1.3079758e-7" ixz="-8.1403365e-8" iyy="1.3112295e-5" iyz="-1.9659314e-6" izz="2.0942871e-5"/>
    </inertial>
    <visual>
      <origin rpy="0.0 0.0 0.0" xyz="0.0 0.0 0.0"/>
      <geometry>
        <mesh filename="./mesh/xm430.obj" scale="0.001 0.001 0.001"/>
      </geometry>
    </visual>
    <collision>
      <origin rpy="0.0 0.0 0.0" xyz="0.0 0.0 0.0"/>
      <geometry>
        <mesh filename="./mesh/xm430.obj" scale="0.001 0.001 0.001"/>
      </geometry>
    </collision>
  </link>
  <link name="0-xm430_2">
    <inertial>
      <origin rpy="0 0 0" xyz="-4.0773796e-3 -1.5304911e-2 -1.6871895e-2"/>
      <mass value="0.082"/>
      <inertia ixx="2.3729564e-5" ixy="-1.3079758e-7" ixz="-8.1403365e-8" iyy="1.3112295e-5" iyz="-1.9659314e-6" izz="2.0942871e-5"/>
    </inertial>
    <visual>
      <origin rpy="0.0 0.0 0.0" xyz="0.0 0.0 0.0"/>
      <geometry>
        <mesh filename="./mesh/xm430.obj" scale="0.001 0.001 0.001"/>
      </geometry>
    </visual>
    <collision>
      <origin rpy="0.0 0.0 0.0" xyz="0.0 0.0 0.0"/>
      <geometry>
        <mesh filename="./mesh/xm430.obj" scale="0.001 0.001 0.001"/>
      </geometry>
    </collision>
  </link>
  <link name="0-base_motor_frame">
    <inertial>
      <origin rpy="0 0 0" xyz="6.48e-08 -0.0015864406 0.0250889877"/>
      <mass value="0.0768049156"/>
      <inertia ixx="5.65659e-05" ixy="-0.0" ixz="1e-10" iyy="5.30145e-05" iyz="1.1663e-06" izz="3.40217e-05"/>
    </inertial>
    <visual>
      <origin rpy="0 0 0" xyz="0 0 0"/>
      <geometry>
        <mesh filename="./mesh/base_motor_frame.obj" scale="0.001 0.001 0.001"/>
      </geometry>
    </visual>
    <collision>
      <origin rpy="0 0 0" xyz="0 0 0"/>
      <geometry>
        <mesh filename="./mesh/base_motor_frame.obj" scale="0.001 0.001 0.001"/>
      </geometry>
    </collision>
  </link>
  <link name="0-dual_servo_shell">
    <inertial>
      <origin rpy="0 0 0" xyz="0.0005322566 -0.0003161331 0.0506920676"/>
      <mass value="0.0258069457"/>
      <inertia ixx="4.11451e-05" ixy="7.82e-08" ixz="-7.721e-07" iyy="4.42386e-05" iyz="2.774e-07" izz="4.8477e-06"/>
    </inertial>
    <visual>
      <origin rpy="0.0 0.0 0.0" xyz="0.0 0.0 0.0"/>
      <geometry>
        <mesh filename="./mesh/dual_servo_shell.stl" scale="0.001 0.001 0.001"/>
      </geometry>
    </visual>
    <collision>
      <origin rpy="0.0 0.0 0.0" xyz="0.0 0.0 0.0"/>
      <geometry>
        <mesh filename="./mesh/dual_servo_shell.stl" scale="0.001 0.001 0.001"/>
      </geometry>
    </collision>
  </link>
  <link name="0-dual_servo_transmission">
    <inertial>
      <origin rpy="0 0 0" xyz="-1.41e-08 0.0095354556 0.0141401617"/>
      <mass value="0.0576887165"/>
      <inertia ixx="2.78223e-05" ixy="5.7e-09" ixz="-0.0" iyy="1.35978e-05" iyz="4.5419e-06" izz="2.50167e-05"/>
    </inertial>
    <visual>
      <origin rpy="0.0 0.0 0.0" xyz="0.0 0.0 0.0"/>
      <geometry>
        <mesh filename="./mesh/dual_servo_transmission_simplified.obj" scale="0.001 0.001 0.001"/>
      </geometry>
    </visual>
    <collision>
      <origin rpy="0.0 0.0 0.0" xyz="0.0 0.0 0.0"/>
      <geometry>
        <mesh filename="./mesh/dual_servo_transmission_simplified.obj" scale="0.001 0.001 0.001"/>
      </geometry>
    </collision>
  </link>
  <link name="0-finger1">
    <inertial>
      <origin rpy="0 0 0" xyz=" -0.0026344221 -0.0673645556 -0.0033892017"/>
      <mass value="0.0273686016"/>
      <inertia ixx="3.82526e-05" ixy="-1.6373e-06" ixz="-1.96e-07" iyy="1.4086e-06" iyz="4.307e-07" izz="3.86145e-05"/>
    </inertial>
    <visual>
      <origin rpy="0.0 0.0 0.0" xyz="0.0 0.0 0.0"/>
      <geometry>
        <mesh filename="./mesh/finger1.obj" scale="0.001 0.001 0.001"/>
      </geometry>
    </visual>
    <collision>
      <origin rpy="0.0 0.0 0.0" xyz="0.0 0.0 0.0"/>
      <geometry>
        <mesh filename="./mesh/finger1.obj" scale="0.001 0.001 0.001"/>
      </geometry>
    </collision>
  </link>
  <link name="0-finger2">
    <inertial>
      <origin rpy="0 0 0" xyz=" -0.0025634596 -0.0642987636 0.003878593"/>
      <mass value="0.0282885857"/>
      <inertia ixx="4.51291e-05" ixy="-1.8472e-06" ixz="1.613e-07" iyy="1.3194e-06" iyz="-1.3204e-06" izz="4.53013e-05"/>
    </inertial>
    <visual>
      <origin rpy="0.0 0.0 0.0" xyz="0.0 0.0 0.0"/>
      <geometry>
        <mesh filename="./mesh/finger2.obj" scale="0.001 0.001 0.001"/>
      </geometry>
    </visual>
    <collision>
      <origin rpy="0.0 0.0 0.0" xyz="0.0 0.0 0.0"/>
      <geometry>
        <mesh filename="./mesh/finger2.obj" scale="0.001 0.001 0.001"/>
      </geometry>
    </collision>
  </link>
  <!--Create joints to connect the parts-->
  <!--Fix the module to module parent link-->
  <joint name="0-module_to_parent" type="fixed">
    <parent link="dummy"/>
    <child link="0-base_motor_frame"/>
    <origin rpy="3.14159265 0 1.570796325" xyz="0 0 0"/>
  </joint>
  <!--Fix the parts which are not supposed to move-->
  <joint name="0-fix_xm430_0" type="fixed">
    <parent link="0-base_motor_frame"/>
    <child link="0-xm430_0"/>
    <origin rpy="0 0 0" xyz="0 0 0.054"/>
  </joint>
  <joint name="0-fix_xm430_1" type="fixed">
    <parent link="0-dual_servo_shell"/>
    <child link="0-xm430_1"/>
    <origin rpy="-1.570796325 0 0" xyz="0 0.019 0.0334"/>
  </joint>
  <joint name="0-fix_xm430_2" type="fixed">
    <parent link="0-xm430_1"/>
    <child link="0-xm430_2"/>
    <origin rpy="0 0 0" xyz="0 -0.0465 0"/>
  </joint>
  <joint name="0-fix_transmission" type="fixed">
    <parent link="0-xm430_2"/>
    <child link="0-dual_servo_transmission"/>
    <origin rpy="0 0 0" xyz="0 0 0"/>
  </joint>
  <!--DoFs, joints corresponding to the degrees of actuation-->
  <joint name="0-dof1" type="revolute">
    <parent link="0-xm430_0"/>
    <child link="0-dual_servo_shell"/>
    <axis xyz="0 0 -1"/>
    <limit effort="1000" lower="-3.14159265" upper="3.14159265" velocity="1000"/>
    <origin rpy="0 0 0" xyz="0 0 0"/>
  </joint>
  <joint name="0-dof2" type="revolute">
    <parent link="0-xm430_2"/>
    <child link="0-finger1"/>
    <axis xyz="0 0 -1"/>
    <limit effort="1000" lower="-1.570796325" upper="1.570796325" velocity="1000"/>
    <origin rpy="0 0 0" xyz="0 0 0.0368"/>
  </joint>
  <joint name="0-dof3" type="revolute">
    <parent link="0-finger1"/>
    <child link="0-finger2"/>
    <axis xyz="0 0 -1"/>
    <limit effort="1000" lower="-2.3561944875" upper="2.3561944875" velocity="1000"/>
    <origin rpy="0 -0.7853981625 0" xyz="-0.0014142 -0.1 0.0014142"/>
  </joint>
  <!--frames that may be helpful-->
  <link name="0-fingertip_frame">
    <geometry>
      <origin rpy="0 0 0" xyz="0 0 0"/>
    </geometry>
  </link>
  <joint name="0-fingertip_frame_fix" type="fixed">
    <parent link="0-finger2"/>
    <child link="0-fingertip_frame"/>
    <origin rpy="0 0 0" xyz="-0.004242 -0.12 -0.004242"/>
  </joint>
</robot>
