<?xml version="1.0"?>
<robot xmlns:xacro="http://www.ros.org/wiki/xacro">
    <!--Import parts from xacro file-->
    <xacro:include filename="parts.urdf.xacro"/>

    <xacro:macro name="module" params="module_prefix parent_link *origin">
        <!--Create all the parts needed to construct the module-->
        <xacro:xm430 module_prefix="${module_prefix}" motor_index="0"/>
        <xacro:xm430 module_prefix="${module_prefix}" motor_index="1"/>
        <xacro:xm430 module_prefix="${module_prefix}" motor_index="2"/>
        <xacro:base_motor_frame module_prefix="${module_prefix}"/>
        <xacro:dual_servo_shell module_prefix="${module_prefix}"/>
        <xacro:dual_servo_transmission module_prefix="${module_prefix}"/>
        <xacro:finger1 module_prefix="${module_prefix}"/>
        <xacro:finger2 module_prefix="${module_prefix}"/>
        

        <!--Create joints to connect the parts-->
        <!--Fix the module to module parent link-->
        <joint name="${module_prefix}-module_to_parent" type="fixed">
            <parent link="${parent_link}"/>
            <child link="${module_prefix}-base_motor_frame"/>
            <xacro:insert_block name="origin"/>
        </joint>
        <!--Fix the parts which are not supposed to move-->
        <joint name="${module_prefix}-fix_xm430_0" type="fixed">
            <parent link="${module_prefix}-base_motor_frame"/>
            <child link="${module_prefix}-xm430_0"/>
            <origin xyz="0 0 0.054" rpy="0 0 0"/>
        </joint>

        <joint name="${module_prefix}-fix_xm430_1" type="fixed">
            <parent link="${module_prefix}-dual_servo_shell"/>
            <child link="${module_prefix}-xm430_1"/>
            <origin xyz="0 0.019 0.0334" rpy="${-1*PI/2.0} 0 0"/>
        </joint>

        <joint name="${module_prefix}-fix_xm430_2" type="fixed">
            <parent link="${module_prefix}-xm430_1"/>
            <child link="${module_prefix}-xm430_2"/>
            <origin xyz="0 -0.0465 0" rpy="0 0 0"/>
        </joint>

        <joint name="${module_prefix}-fix_transmission" type="fixed">
            <parent link="${module_prefix}-xm430_2"/>
            <child link="${module_prefix}-dual_servo_transmission"/>
            <origin xyz="0 0 0" rpy="0 0 0"/>
        </joint>

        <!--DoFs, joints corresponding to the degrees of actuation-->
        <joint name="${module_prefix}-dof1" type="revolute">
            <parent link="${module_prefix}-xm430_0"/>
            <child link="${module_prefix}-dual_servo_shell"/>
            <axis xyz="0 0 -1"/>
            <limit effort="1000" lower="${-1*PI}" upper="${PI}" velocity="1000"/>
            <origin xyz="0 0 0" rpy="0 0 0"/>
        </joint>

        <joint name="${module_prefix}-dof2" type="revolute">
            <parent link="${module_prefix}-xm430_2"/>
            <child link="${module_prefix}-finger1"/>
            <axis xyz="0 0 -1"/>
            <limit effort="1000" lower="${-1*PI/2}" upper="${PI/2}" velocity="1000"/>
            <origin xyz="0 0 0.0368" rpy="0 0 0"/>
        </joint>

        <joint name="${module_prefix}-dof3" type="revolute">
            <parent link="${module_prefix}-finger1"/>
            <child link="${module_prefix}-finger2"/>
            <axis xyz="0 0 1"/>
            <limit effort="1000" lower="${-3*PI/4}" upper="${3*PI/4}" velocity="1000"/>
            <origin xyz="-0.0014142 -0.1 0.0014142" rpy="0 ${-1*PI/4.0} 0"/>    
        </joint>

        <!--frames that may be helpful-->
        <link name="${module_prefix}-fingertip_frame">
            <geometry>
                <origin xyz="0 0 0" rpy="0 0 0"/>
            </geometry>
        </link>

        <joint name="${module_prefix}-fingertip_frame_fix" type="fixed">
            <parent link="${module_prefix}-finger2"/>
            <child link="${module_prefix}-fingertip_frame"/>
            <origin xyz="-0.004242 -0.12 -0.004242" rpy="0 0 0"/>
        </joint>

    </xacro:macro>

</robot>
